Workbook
Name d: #REF!
Name d: #REF!
Name d: #REF!
Name DBS: #REF!
Name DBS: #REF!
Name DBS: #REF!
Name dd: #REF!
Name dd: #REF!
Name dd: #REF!
Name ddd: #REF!
Name ddd: #REF!
Name ddd: #REF!
Name kerusakanlistrik: Sheet5!$B$3:$C$8
Name med: #REF!
Name med: #REF!
Name med: #REF!
Name MEDALI: #REF!
Name MEDALI: #REF!
Name MEDALI: #REF!
Name medalii: #REF!
Name medalii: #REF!
Name medalii: #REF!
Name Print_Area_MI: #N/A
Name REKAP: '[1]BEST OF'!#REF!
Name REKAP: '[1]BEST OF'!#REF!
Name REKAP: '[1]BEST OF'!#REF!
Name rrr: '[1]BEST OF'!#REF!
Name rrr: '[1]BEST OF'!#REF!
Name rrr: '[1]BEST OF'!#REF!
Name SMA: #REF!
Name SMA: #REF!
Name SMA: #REF!
Name TOTAL: #REF!
Name TOTAL: #REF!
Name TOTAL: #REF!

Sheet FORM KERUSAKAN
B2: FORMULIR PENILAIAN KERUSAKAN BANGUNAN
B4: Nama Sekolah | D4: : | E4: SDN 1 Tegal
B5: NPSN | D5: : | E5: 20….
B6: Nama Bangunan | D6: : | E6: Bangunan Kelas 1 -3
B7: NUP (No Urut Perolehan) | D7: :
B8: Alamat | D8: : | E8: Jl. Timur Barat
B9: Kabupaten/Kota | D9: : | E9: Kabupaten | H9: Provinsi
B10: Koordinat | D10: :
B11: Luas Bangunan | D11: : | E11: 100 | F11: m2 | O11: Jumlah Lantai : | S11: 1
B13: NO | C13: SISTEM | D13: KOMPONEN | F13: SATUAN | G13: VOLUME SELURUH KOMPONEN | H13: TAHAP 1 - PENGAMATAN VISUAL ADA / TDKNYA KERUSAKAN DAN INDIKASI DAMPAK KERUSAKAN TERHADAP KESELAMATAN PEMANFAATAN RUANGAN / BANGUNAN | I13: TAHAP 2 - HITUNG VOLUME KERUSAKAN KOMPONEN BERDASARKAN KLASIFIKASI KERUSAKAN | P13: PERHITUNGAN TINGKAT KERUSAKAN KOMPONEN | X13: BOBOT KOMPONEN | Y13: TINGKAT KERUSAKAN KOMPONEN THD MASSA BANGUNAN / RUANGAN
I14: Tdk Rusak | J14: Rusak, dengan Tingkat Kerusakan: | O14: Komponen Tdk Sesuai / Tdk Ada
J15: Sangat Ringan | K15: Ringan | L15: Sedang | M15: Berat | N15: Sangat Berat | P15: 1 | Q15: 2 | R15: 3 | S15: 4 | T15: 5 | U15: 6 | V15: 7 | W15: TOTAL
I16: 1 | J16: 2 | K16: 3 | L16: 4 | M16: 5 | N16: 6 | O16: 7 | P16: 0 | Q16: 0.2 | R16: 0.35 | S16: 0.5 | T16: 0.7 | U16: 0.85 | V16: 1
B17: (1) | C17: (2) | D17: (3) | F17: (4) | G17: (5) | H17: (6) | I17: (7) | J17: (8) | K17: (9) | L17: (10) | M17: (11) | N17: (12) | O17: (13) | P17: (14) | Q17: (15) | R17: (16) | S17: (17) | T17: (18) | U17: (19) | V17: (20) | W17: (21) | X17: (22) | Y17: (23)
B18: 1 | C18: STRUKTUR | D18: Pondasi & Sloof | F18: Estimasi | H18: Tidak ada kerusakan | I18: Pondasi diindikasi dalam kondisi baik | W18: =VLOOKUP(I18,Sheet5!B12:C18,2,FALSE) -> 0 | X18: 0.12 | Y18: =W18*X18 -> 0
D19: Kolom | F19: unit | G19: 10 | P19: =I19/G19*$P$16 -> 0 | Q19: =J19/G19*$Q$16 -> 0 | R19: =K19/G19*$R$16 -> 0 | S19: =L19/G19*$S$16 -> 0 | T19: =M19/G19*$T$16 -> 0 | U19: =N19/G19*$U$16 -> 0 | V19: =O19/G19*$V$16 -> 0 | W19: =SUM(P19:V19) -> 0 | X19: 0.1 | Y19: =W19*X19 -> 0
D20: Balok | F20: unit | G20: 4 | P20: =I20/G20*$P$16 -> 0 | Q20: =J20/G20*$Q$16 -> 0 | R20: =K20/G20*$R$16 -> 0 | S20: =L20/G20*$S$16 -> 0 | T20: =M20/G20*$T$16 -> 0 | U20: =N20/G20*$U$16 -> 0 | V20: =O20/G20*$V$16 -> 0 | W20: =SUM(P20:V20) -> 0 | X20: 0.08 | Y20: =W20*X20 -> 0
D21: Atap | F21: % | G21: 100 | H21: Tidak ada kerusakan | P21: =I21/G21*100*$P$16 -> 0 | Q21: =J21/G21*100*$Q$16 -> 0 | R21: =K21/G21*100*$R$16 -> 0 | S21: =L21/G21*100*$S$16 -> 0 | T21: =M21/G21*100*$T$16 -> 0 | U21: =N21/G21*100*$U$16 -> 0 | V21: =O21/G21*100*$V$16 -> 0 | W21: =SUM(P21:V21) -> 0 | X21: 0.07 | Y21: =W21*X21 -> 0
B22: 2 | C22: ARSITEKTUR | D22: Dinding / Partisi | F22: % | G22: 100 | H22: Tidak ada kerusakan | P22: =I22/G22*100*$P$16 -> 0 | Q22: =J22/G22*100*$Q$16 -> 0 | R22: =K22/G22*100*$R$16 -> 0 | S22: =L22/G22*100*$S$16 -> 0 | T22: =M22/G22*100*$T$16 -> 0 | U22: =N22/G22*100*$U$16 -> 0 | V22: =O22/G22*100*$V$16 -> 0 | W22: =SUM(P22:V22) -> 0 | X22: 0.215 | Y22: =W22*X22 -> 0
D23: Plafond | F23: % | G23: 100 | P23: =I23/G23*100*$P$16 -> 0 | Q23: =J23/G23*100*$Q$16 -> 0 | R23: =K23/G23*100*$R$16 -> 0 | S23: =L23/G23*100*$S$16 -> 0 | T23: =M23/G23*100*$T$16 -> 0 | U23: =N23/G23*100*$U$16 -> 0 | V23: =O23/G23*100*$V$16 -> 0 | W23: =SUM(P23:V23) -> 0 | X23: 0.1 | Y23: =W23*X23 -> 0
D24: Lantai | F24: % | G24: 100 | P24: =I24/G24*100*$P$16 -> 0 | Q24: =J24/G24*100*$Q$16 -> 0 | R24: =K24/G24*100*$R$16 -> 0 | S24: =L24/G24*100*$S$16 -> 0 | T24: =M24/G24*100*$T$16 -> 0 | U24: =N24/G24*100*$U$16 -> 0 | V24: =O24/G24*100*$V$16 -> 0 | W24: =SUM(P24:V24) -> 0 | X24: 0.145 | Y24: =W24*X24 -> 0
D25: Kusen | F25: unit | G25: 1 | P25: =I25/G25*$P$16 -> 0 | Q25: =J25/G25*$Q$16 -> 0 | R25: =K25/G25*$R$16 -> 0 | S25: =L25/G25*$S$16 -> 0 | T25: =M25/G25*$T$16 -> 0 | U25: =N25/G25*$U$16 -> 0 | V25: =O25/G25*$V$16 -> 0 | W25: =SUM(P25:V25) -> 0 | X25: 0.01 | Y25: =W25*X25 -> 0
D26: Pintu | F26: unit | G26: 1 | P26: =I26/G26*$P$16 -> 0 | Q26: =J26/G26*$Q$16 -> 0 | R26: =K26/G26*$R$16 -> 0 | S26: =L26/G26*$S$16 -> 0 | T26: =M26/G26*$T$16 -> 0 | U26: =N26/G26*$U$16 -> 0 | V26: =O26/G26*$V$16 -> 0 | W26: =SUM(P26:V26) -> 0 | X26: 0.015 | Y26: =W26*X26 -> 0
D27: Jendela | F27: unit | G27: 1 | P27: =I27/G27*$P$16 -> 0 | Q27: =J27/G27*$Q$16 -> 0 | R27: =K27/G27*$R$16 -> 0 | S27: =L27/G27*$S$16 -> 0 | T27: =M27/G27*$T$16 -> 0 | U27: =N27/G27*$U$16 -> 0 | V27: =O27/G27*$V$16 -> 0 | W27: =SUM(P27:V27) -> 0 | X27: 0.02 | Y27: =W27*X27 -> 0
D28: Finishing Plafond | F28: % | G28: 100 | P28: =I28/G28*100*$P$16 -> 0 | Q28: =J28/G28*100*$Q$16 -> 0 | R28: =K28/G28*100*$R$16 -> 0 | S28: =L28/G28*100*$S$16 -> 0 | T28: =M28/G28*100*$T$16 -> 0 | U28: =N28/G28*100*$U$16 -> 0 | V28: =O28/G28*100*$V$16 -> 0 | W28: =SUM(P28:V28) -> 0 | X28: 0.03 | Y28: =W28*X28 -> 0
D29: Finishing Dinding | F29: % | G29: 100 | P29: =I29/G29*100*$P$16 -> 0 | Q29: =J29/G29*100*$Q$16 -> 0 | R29: =K29/G29*100*$R$16 -> 0 | S29: =L29/G29*100*$S$16 -> 0 | T29: =M29/G29*100*$T$16 -> 0 | U29: =N29/G29*100*$U$16 -> 0 | V29: =O29/G29*100*$V$16 -> 0 | W29: =SUM(P29:V29) -> 0 | X29: 0.04 | Y29: =W29*X29 -> 0
D30: Finishing Kusen & Pintu | F30: % | G30: 100 | P30: =I30/G30*100*$P$16 -> 0 | Q30: =J30/G30*100*$Q$16 -> 0 | R30: =K30/G30*100*$R$16 -> 0 | S30: =L30/G30*100*$S$16 -> 0 | T30: =M30/G30*100*$T$16 -> 0 | U30: =N30/G30*100*$U$16 -> 0 | V30: =O30/G30*100*$V$16 -> 0 | W30: =SUM(P30:V30) -> 0 | X30: 0.02 | Y30: =W30*X30 -> 0
B31: 3 | C31: UTILITAS | D31: Instalasi Listrik | F31: Estimasi | I31: Jaringan listrik dalam kondisi baik | W31: =VLOOKUP(I31,Sheet5!B3:C9,2,FALSE) -> 0 | X31: 0.01 | Y31: =W31*X31 -> 0
D32: Instalasi Air Bersih | F32: Estimasi | I32: Sistem penyediaan air dalam kondisi baik | W32: =VLOOKUP(I32,Sheet5!B21:C27,2,FALSE) -> 0 | X32: 0.01 | Y32: =W32*X32 -> 0
D33: Drainase Limbah | F33: m1 | G33: 1 | P33: =I33/G33*$P$16 -> 0 | Q33: =J33/G33*$Q$16 -> 0 | R33: =K33/G33*$R$16 -> 0 | S33: =L33/G33*$S$16 -> 0 | T33: =M33/G33*$T$16 -> 0 | U33: =N33/G33*$U$16 -> 0 | V33: =O33/G33*$V$16 -> 0 | W33: =SUM(P33:V33) -> 0 | X33: 0.015 | Y33: =W33*X33 -> 0
H34: =IF(H18=Sheet1!G5,"Rusak Berat",IF(H19=Sheet1!G5,"Rusak Berat",IF(H20=Sheet1!G5,"Rusak Berat",IF(H21=Sheet1!G5,"Rusak Berat",IF(H22=Sheet1!G5,"Rusak Berat",IF(H18=Sheet1!G6,"Hitung Kerusakan",IF(H19=Sheet1!G6,"Hitung Kerusakan",IF(H20=Sheet1!G6,"Hitung Kerusakan",IF(H21=Sheet1!G6,"Hitung Kerusakan","Cek Kerusakan Komponen Lain"))))))))) -> Cek Kerusakan Komponen Lain | P34: TOTAL NILAI KERUSAKAN MASSA BANGUNAN / RUANGAN= | Y34: =SUM(Y18:Y33) -> 0
P36: KESIMPULAN TINGKAT KERUSAKAN MASSA BANGUNAN / RUANGAN = | Y36: =IF(H34="Rusak Berat","Rusak Berat",Y37) -> Tidak Ada Kerusakan
Y37: =IF(Y34=0,"Tidak Ada Kerusakan",IF(Y34<=0.3,"Rusak Ringan",IF(Y34>0.45,"Rusak Berat","Rusak Sedang"))) -> Tidak Ada Kerusakan
W39: Tingkat Kerusakan
W40: Ringan | Y40: : ≤ 30%
B41: SKETSA DENAH BANGUNAN | W41: Sedang | Y41: : > 30% - 45%
W42: Berat | Y42: : > 45%
W44: TIM SURVEI :
W45: Petugas Survey
W48: (.................................................)
...

Sheet New FORM KERUSAKAN
B2: FORMULIR PENILAIAN KERUSAKAN BANGUNAN
B4: Nama Sekolah | D4: :
B5: NPSN | D5: :
B6: Nama Bangunan | D6: :
B7: NUP (No Urut Perolehan) | D7: :
B8: Alamat | D8: :
B9: Kabupaten/Kota | D9: : | H9: Provinsi
B10: Koordinat | D10: :
B11: Luas Bangunan | D11: : | F11: m2 | N11: Jumlah Lantai : | T11: 1
B13: NO | C13: SISTEM | D13: KOMPONEN | F13: SATUAN | G13: VOLUME SELURUH KOMPONEN | H13: TAHAP 2 - HITUNG VOLUME KERUSAKAN KOMPONEN BERDASARKAN KLASIFIKASI KERUSAKAN | P13: TAHAP 1 - PENGAMATAN VISUAL ADA / TDKNYA KERUSAKAN DAN INDIKASI DAMPAK KERUSAKAN TERHADAP KESELAMATAN PEMANFAATAN RUANGAN / BANGUNAN | Q13: PERHITUNGAN TINGKAT KERUSAKAN KOMPONEN | Y13: BOBOT KOMPONEN | Z13: TINGKAT KERUSAKAN KOMPONEN THD MASSA BANGUNAN / RUANGAN
H14: Tdk Rusak | I14: Rusak, dengan Tingkat Kerusakan: | N14: Komponen Tdk Sesuai / Tdk Ada | O14: Keterangan
I15: Sangat Ringan | J15: Ringan | K15: Sedang | L15: Berat | M15: Sangat Berat | Q15: 1 | R15: 2 | S15: 3 | T15: 4 | U15: 5 | V15: 6 | W15: 7 | X15: TOTAL
H16: 1 | I16: 2 | J16: 3 | K16: 4 | L16: 5 | M16: 6 | N16: 7 | Q16: 0 | R16: 0.2 | S16: 0.35 | T16: 0.5 | U16: 0.7 | V16: 0.85 | W16: 1
B17: (1) | C17: (2) | D17: (3) | F17: (4) | G17: (5) | H17: (6) | I17: (7) | J17: (8) | K17: (9) | L17: (10) | M17: (11) | N17: (12) | P17: (13) | Q17: (14) | R17: (15) | S17: (16) | T17: (17) | U17: (18) | V17: (19) | W17: (20) | X17: (21) | Y17: (22) | Z17: (23)
B18: 1 | C18: STRUKTUR | D18: Pondasi & Sloof | F18: Estimasi | H18: Pondasi diindikasi dalam kondisi baik | P18: =IF(H18=Sheet5!B12,"Tidak ada kerusakan",IF(H18=Sheet5!B13,"Tidak Membahayakan keselamatan",IF(H18=Sheet5!B14,"Membahayakan keselamatan",IF(H18=Sheet5!B15,"Membahayakan keselamatan",IF(H18=Sheet5!B16,"Membahayakan keselamatan",IF(H18=Sheet5!B17,"Membahayakan keselamatan",IF(H18=Sheet5!B18,"Tidak Membahayakan keselamatan"))))))) -> Tidak ada kerusakan | X18: =VLOOKUP(H18,Sheet5!B12:C18,2,FALSE) -> 0 | Y18: 0.12 | Z18: =X18*Y18 -> 0 | AB18: Tidak ada kerusakan
D19: Kolom | F19: unit | G19: 8 | O19: =IF(G19=0,"Input Vol Seluruh Komponen",IF(H19+I19+J19+K19+L19+M19+N19=G19,"OK",IF(H19+I19+J19+K19+L19+M19+N19<G19,"Volume Kurang",IF(H19+I19+J19+K19+L19+M19+N19>G19,"Volume Lebih",IF(H19+I19+J19+K19+L19+M19+N19=0,"blank"))))) -> Volume Kurang | P19: =IF(H19=G19,"Tidak ada kerusakan",IF(K19>=0.3*G19,"Membahayakan keselamatan",IF(L19>=2,"Membahayakan keselamatan",IF(M19>=1,"Membahayakan keselamatan",IF(K19+L19+M19>=0.3*G19,"Membahayakan keselamatan",IF(L19+M19>=2,"Membahayakan keselamatan",IF(H19+I19+J19+K19+L19+M19+N19=0,"Tidak ada kerusakan","Tidak membahayakan keselamatan"))))))) -> Tidak ada kerusakan | Q19: =H19/G19*$Q$16 -> 0 | R19: =I19/G19*$R$16 -> 0 | S19: =J19/G19*$S$16 -> 0 | T19: =K19/G19*$T$16 -> 0 | U19: =L19/G19*$U$16 -> 0 | V19: =M19/G19*$V$16 -> 0 | W19: =N19/G19*$W$16 -> 0 | X19: =SUM(Q19:W19) -> 0 | Y19: 0.1 | Z19: =X19*Y19 -> 0
D20: Balok | F20: unit | G20: 8 | O20: =IF(G20=0,"Input Vol Seluruh Komponen",IF(H20+I20+J20+K20+L20+M20+N20=G20,"OK",IF(H20+I20+J20+K20+L20+M20+N20<G20,"Volume Kurang",IF(H20+I20+J20+K20+L20+M20+N20>G20,"Volume Lebih",IF(H20+I20+J20+K20+L20+M20+N20=0,"blank"))))) -> Volume Kurang | P20: =IF(H20=G20,"Tidak ada kerusakan",IF(K20>=0.3*G20,"Membahayakan keselamatan",IF(L20>=2,"Membahayakan keselamatan",IF(M20>=1,"Membahayakan keselamatan",IF(K20+L20+M20>=0.3*G20,"Membahayakan keselamatan",IF(L20+M20>=2,"Membahayakan keselamatan",IF(H20+I20+J20+K20+L20+M20+N20=0,"Tidak ada kerusakan","Tidak membahayakan keselamatan"))))))) -> Tidak ada kerusakan | Q20: =H20/G20*$Q$16 -> 0 | R20: =I20/G20*$R$16 -> 0 | S20: =J20/G20*$S$16 -> 0 | T20: =K20/G20*$T$16 -> 0 | U20: =L20/G20*$U$16 -> 0 | V20: =M20/G20*$V$16 -> 0 | W20: =N20/G20*$W$16 -> 0 | X20: =SUM(Q20:W20) -> 0 | Y20: 0.08 | Z20: =X20*Y20 -> 0
D21: Atap | F21: % | G21: 1 | O21: =IF(H21+I21+J21+K21+L21+M21+N21=0,"Input Volume",IF(H21+I21+J21+K21+L21+M21+N21=G21,"OK",IF(H21+I21+J21+K21+L21+M21+N21<G21,"Volume kurang",IF(H21+I21+J21+K21+L21+M21+N21>G21,"Volume Kelebihan")))) -> Input Volume | P21: =IF(H21=100%,"Tidak ada kerusakan",IF(K21>=30%,"Membahayakan keselamatan",IF(L21>=20%,"Membahayakan keselamatan",IF(M21>=10%,"Membahayakan keselamatan",IF(K21+L21+M21>=30%,"Membahayakan keselamatan",IF(L21+M21>=20%,"Membahayakan keselamatan",IF(H21+I21+J21+K21+L21+M21+N21=0%,"Tidak ada kerusakan","Tidak membahayakan keselamatan"))))))) -> Tidak ada kerusakan | Q21: =H21/G21*100*$Q$16 -> 0 | R21: =I21/G21*100*$R$16 -> 0 | S21: =J21/G21*100*$S$16 -> 0 | T21: =K21/G21*100*$T$16 -> 0 | U21: =L21/G21*100*$U$16 -> 0 | V21: =M21/G21*100*$V$16 -> 0 | W21: =N21/G21*100*$W$16 -> 0 | X21: =(SUM(Q21:W21))/100 -> 0 | Y21: 0.07 | Z21: =X21*Y21 -> 0
B22: 2 | C22: ARSITEKTUR | D22: Dinding / Partisi | F22: % | G22: 1 | O22: =IF(H22+I22+J22+K22+L22+M22+N22=0,"Input Volume",IF(H22+I22+J22+K22+L22+M22+N22=G22,"OK",IF(H22+I22+J22+K22+L22+M22+N22<G22,"Volume kurang",IF(H22+I22+J22+K22+L22+M22+N22>G22,"Volume Kelebihan")))) -> Input Volume | P22: =IF(H22=100%,"Tidak ada kerusakan",IF(L22>=30%,"Membahayakan keselamatan",IF(M22>=25%,"Membahayakan keselamatan",IF(L22+M22>=30%,"Membahayakan keselamatan",IF(H22+I22+J22+K22+L22+M22+N22=0%,"Tidak ada kerusakan","Tidak membahayakan keselamatan"))))) -> Tidak ada kerusakan | Q22: =H22/G22*100*$Q$16 -> 0 | R22: =I22/G22*100*$R$16 -> 0 | S22: =J22/G22*100*$S$16 -> 0 | T22: =K22/G22*100*$T$16 -> 0 | U22: =L22/G22*100*$U$16 -> 0 | V22: =M22/G22*100*$V$16 -> 0 | W22: =N22/G22*100*$W$16 -> 0 | X22: =(SUM(Q22:W22))/100 -> 0 | Y22: 0.215 | Z22: =X22*Y22 -> 0
D23: Plafond | F23: % | G23: 1 | O23: =IF(H23+I23+J23+K23+L23+M23+N23=0,"Input Volume",IF(H23+I23+J23+K23+L23+M23+N23=G23,"OK",IF(H23+I23+J23+K23+L23+M23+N23<G23,"Volume kurang",IF(H23+I23+J23+K23+L23+M23+N23>G23,"Volume Kelebihan")))) -> Input Volume | Q23: =H23/G23*100*$Q$16 -> 0 | R23: =I23/G23*100*$R$16 -> 0 | S23: =J23/G23*100*$S$16 -> 0 | T23: =K23/G23*100*$T$16 -> 0 | U23: =L23/G23*100*$U$16 -> 0 | V23: =M23/G23*100*$V$16 -> 0 | W23: =N23/G23*100*$W$16 -> 0 | X23: =(SUM(Q23:W23))/100 -> 0 | Y23: 0.1 | Z23: =X23*Y23 -> 0
D24: Lantai | F24: % | G24: 1 | O24: =IF(H24+I24+J24+K24+L24+M24+N24=0,"Input Volume",IF(H24+I24+J24+K24+L24+M24+N24=G24,"OK",IF(H24+I24+J24+K24+L24+M24+N24<G24,"Volume kurang",IF(H24+I24+J24+K24+L24+M24+N24>G24,"Volume Kelebihan")))) -> Input Volume | Q24: =H24/G24*100*$Q$16 -> 0 | R24: =I24/G24*100*$R$16 -> 0 | S24: =J24/G24*100*$S$16 -> 0 | T24: =K24/G24*100*$T$16 -> 0 | U24: =L24/G24*100*$U$16 -> 0 | V24: =M24/G24*100*$V$16 -> 0 | W24: =N24/G24*100*$W$16 -> 0 | X24: =(SUM(Q24:W24))/100 -> 0 | Y24: 0.145 | Z24: =X24*Y24 -> 0
D25: Kusen | F25: unit | G25: 1 | O25: =IF(G25=0,"Input Vol Seluruh Komponen",IF(H25+I25+J25+K25+L25+M25+N25=G25,"OK",IF(H25+I25+J25+K25+L25+M25+N25<G25,"Volume Kurang",IF(H25+I25+J25+K25+L25+M25+N25>G25,"Volume Lebih",IF(H25+I25+J25+K25+L25+M25+N25=0,"blank"))))) -> Volume Kurang | Q25: =H25/G25*$Q$16 -> 0 | R25: =I25/G25*$R$16 -> 0 | S25: =J25/G25*$S$16 -> 0 | T25: =K25/G25*$T$16 -> 0 | U25: =L25/G25*$U$16 -> 0 | V25: =M25/G25*$V$16 -> 0 | W25: =N25/G25*$W$16 -> 0 | X25: =SUM(Q25:W25) -> 0 | Y25: 0.01 | Z25: =X25*Y25 -> 0
D26: Pintu | F26: unit | G26: 1 | O26: =IF(G26=0,"Input Vol Seluruh Komponen",IF(H26+I26+J26+K26+L26+M26+N26=G26,"OK",IF(H26+I26+J26+K26+L26+M26+N26<G26,"Volume Kurang",IF(H26+I26+J26+K26+L26+M26+N26>G26,"Volume Lebih",IF(H26+I26+J26+K26+L26+M26+N26=0,"blank"))))) -> Volume Kurang | Q26: =H26/G26*$Q$16 -> 0 | R26: =I26/G26*$R$16 -> 0 | S26: =J26/G26*$S$16 -> 0 | T26: =K26/G26*$T$16 -> 0 | U26: =L26/G26*$U$16 -> 0 | V26: =M26/G26*$V$16 -> 0 | W26: =N26/G26*$W$16 -> 0 | X26: =SUM(Q26:W26) -> 0 | Y26: 0.015 | Z26: =X26*Y26 -> 0
D27: Jendela | F27: unit | G27: 1 | O27: =IF(G27=0,"Input Vol Seluruh Komponen",IF(H27+I27+J27+K27+L27+M27+N27=G27,"OK",IF(H27+I27+J27+K27+L27+M27+N27<G27,"Volume Kurang",IF(H27+I27+J27+K27+L27+M27+N27>G27,"Volume Lebih",IF(H27+I27+J27+K27+L27+M27+N27=0,"blank"))))) -> Volume Kurang | Q27: =H27/G27*$Q$16 -> 0 | R27: =I27/G27*$R$16 -> 0 | S27: =J27/G27*$S$16 -> 0 | T27: =K27/G27*$T$16 -> 0 | U27: =L27/G27*$U$16 -> 0 | V27: =M27/G27*$V$16 -> 0 | W27: =N27/G27*$W$16 -> 0 | X27: =SUM(Q27:W27) -> 0 | Y27: 0.02 | Z27: =X27*Y27 -> 0
D28: Finishing Plafond | F28: % | G28: 1 | O28: =IF(H28+I28+J28+K28+L28+M28+N28=0,"Input Volume",IF(H28+I28+J28+K28+L28+M28+N28=G28,"OK",IF(H28+I28+J28+K28+L28+M28+N28<G28,"Volume kurang",IF(H28+I28+J28+K28+L28+M28+N28>G28,"Volume Kelebihan")))) -> Input Volume | Q28: =H28/G28*100*$Q$16 -> 0 | R28: =I28/G28*100*$R$16 -> 0 | S28: =J28/G28*100*$S$16 -> 0 | T28: =K28/G28*100*$T$16 -> 0 | U28: =L28/G28*100*$U$16 -> 0 | V28: =M28/G28*100*$V$16 -> 0 | W28: =N28/G28*100*$W$16 -> 0 | X28: =(SUM(Q28:W28))/100 -> 0 | Y28: 0.03 | Z28: =X28*Y28 -> 0
D29: Finishing Dinding | F29: % | G29: 1 | O29: =IF(H29+I29+J29+K29+L29+M29+N29=0,"Input Volume",IF(H29+I29+J29+K29+L29+M29+N29=G29,"OK",IF(H29+I29+J29+K29+L29+M29+N29<G29,"Volume kurang",IF(H29+I29+J29+K29+L29+M29+N29>G29,"Volume Kelebihan")))) -> Input Volume | Q29: =H29/G29*100*$Q$16 -> 0 | R29: =I29/G29*100*$R$16 -> 0 | S29: =J29/G29*100*$S$16 -> 0 | T29: =K29/G29*100*$T$16 -> 0 | U29: =L29/G29*100*$U$16 -> 0 | V29: =M29/G29*100*$V$16 -> 0 | W29: =N29/G29*100*$W$16 -> 0 | X29: =(SUM(Q29:W29))/100 -> 0 | Y29: 0.04 | Z29: =X29*Y29 -> 0
D30: Finishing Kusen & Pintu | F30: % | G30: 1 | O30: =IF(H30+I30+J30+K30+L30+M30+N30=0,"Input Volume",IF(H30+I30+J30+K30+L30+M30+N30=G30,"OK",IF(H30+I30+J30+K30+L30+M30+N30<G30,"Volume kurang",IF(H30+I30+J30+K30+L30+M30+N30>G30,"Volume Kelebihan")))) -> Input Volume | Q30: =H30/G30*100*$Q$16 -> 0 | R30: =I30/G30*100*$R$16 -> 0 | S30: =J30/G30*100*$S$16 -> 0 | T30: =K30/G30*100*$T$16 -> 0 | U30: =L30/G30*100*$U$16 -> 0 | V30: =M30/G30*100*$V$16 -> 0 | W30: =N30/G30*100*$W$16 -> 0 | X30: =(SUM(Q30:W30))/100 -> 0 | Y30: 0.02 | Z30: =X30*Y30 -> 0
B31: 3 | C31: UTILITAS | D31: Instalasi Listrik | F31: Estimasi | H31: Jaringan listrik dalam kondisi baik | X31: =VLOOKUP(H31,Sheet5!B3:C9,2,FALSE) -> 0 | Y31: 0.01 | Z31: =X31*Y31 -> 0
D32: Instalasi Air Bersih | F32: Estimasi | H32: Sistem penyediaan air dalam kondisi baik | X32: =VLOOKUP(H32,Sheet5!B21:C27,2,FALSE) -> 0 | Y32: 0.01 | Z32: =X32*Y32 -> 0
D33: Drainase Limbah | F33: m1 | G33: 1 | O33: =IF(H33+I33+J33+K33+L33+M33+N33=0,"Input Volume",IF(H33+I33+J33+K33+L33+M33+N33=G33,"OK",IF(H33+I33+J33+K33+L33+M33+N33<G33,"Volume kurang",IF(H33+I33+J33+K33+L33+M33+N33>G33,"Volume Kelebihan")))) -> Input Volume | Q33: =H33/G33*$Q$16 -> 0 | R33: =I33/G33*$R$16 -> 0 | S33: =J33/G33*$S$16 -> 0 | T33: =K33/G33*$T$16 -> 0 | U33: =L33/G33*$U$16 -> 0 | V33: =M33/G33*$V$16 -> 0 | W33: =N33/G33*$W$16 -> 0 | X33: =SUM(Q33:W33) -> 0 | Y33: 0.015 | Z33: =X33*Y33 -> 0
P34: =IF(P18=Sheet1!C5,"Membahayakan Keselamatan",IF(P19=Sheet1!C5,"Membahayakan Keselamatan",IF(P20=Sheet1!C5,"Membahayakan Keselamatan",IF(P21=Sheet1!C5,"Membahayakan Keselamatan",IF(P22=Sheet1!C5,"Membahayakan Keselamatan",IF(P18=Sheet1!C6,"Tidak Membahayakan Keselamatan",IF(P19=Sheet1!C6,"Tidak Membahayakan Keselamatan",IF(P20=Sheet1!C6,"Tidak Membahayakan Keselamatan",IF(P21=Sheet1!C6,"Tidak Membahayakan Keselamatan",IF(P22=Sheet1!C6,"Tidak Membahayakan Keselamatan","Cek Kerusakan Komponen Lain")))))))))) -> Cek Kerusakan Komponen Lain | Q34: TOTAL NILAI KERUSAKAN MASSA BANGUNAN / RUANGAN= | Z34: =SUM(Z18:Z33) -> 0
Q36: KESIMPULAN TINGKAT KERUSAKAN MASSA BANGUNAN / RUANGAN = | Z36: =IF(P34="Membahayakan Keselamatan","Rusak Berat",Z37) -> Tidak Ada Kerusakan
Z37: =IF(Z34=0,"Tidak Ada Kerusakan",IF(Z34<=0.3,"Rusak Ringan",IF(Z34>0.45,"Rusak Berat","Rusak Sedang"))) -> Tidak Ada Kerusakan
X39: Tingkat Kerusakan
X40: Ringan | Z40: : ≤ 30%
B41: SKETSA DENAH BANGUNAN | X41: Sedang | Z41: : > 30% - 45%
X42: Berat | Z42: : > 45%
X44: TIM SURVEI :
X45: Petugas Survey
X48: (.................................................)
...

Sheet Sheet3

Sheet Sheet1
A2: INDIKASI DAMPAK KERUSAKAN
B3: TERHADAP KESELAMATAN
C4: Tidak ada kerusakan
C5: Membahayakan keselamatan | G5: Ada kerusakan yang diindikasi membahayakan keselamatan pemanfaatan ruang/bangunan
C6: Tidak membahayakan keselamatan | G6: Ada kerusakan, namun diindikasi tidak membahayakan keselamatan pemanfaatan ruang/bangunan
B8: TERHADAP KEBERFUNGSIAN
C9: Tidak ada kerusakan
C10: Ada kerusakan yang mengakibatkan ruang/bangunan tidak dapat difungsikan
C11: Ada kerusakan, namun ruang/bangunan masih dapat difungsikan

Sheet Sheet5
B2: Kerusakan listrik
A3: 1 | B3: Jaringan listrik dalam kondisi baik | C3: 0
A4: 2 | B4: Sebagian kecil komponen dari panel-panel LP rusak, ada sedikit jalur kabel instalasi shortage, sebagian kecil armature rusak ringan, sehingga biaya perbaikan kurang dari 10% dari biaya instalasi baru | C4: 0.2
A5: 3 | B5: Beberapa komponen dari panel-panel LP rusak, sebagian kecil jalur kabel instalasi shortage, sehingga armature rusak ringan, sehingga biaya perbaikan 10-25% dari biaya instalasi baru | C5: 0.35
A6: 4 | B6: Beberapa komponen dari panel-panel LP rusak, sebagian kecil jalur kabel instalasi shortage, sehingga armature rusak berat dan ringan, sehingga biaya perbaikan 25-50% dari biaya instalasi baru | C6: 0.5
A7: 5 | B7: Sebagian besar komponen panel-panel LP rusak, sebagian besar kabel instalasi shortage, sebagian besar armature rusak, sehingga biaya perbaikan 50-65 % dari instalasi baru | C7: 0.7
A8: 6 | B8: Sebagian besar komponen panel-panel LP rusak, sebagian besar kabel instalasi shortage, seluruh armature rusak berat, sehingga biaya perbaikan lebih dari 65 % dari instalasi baru | C8: 0.85
A9: 7 | B9: Material, dimensi, dan konstruksi jaringan listrik diindikasi tidak sesuai dengan persyaratan teknis (merujuk pada Rencana Teknis apabila ada, Petunjuk Teknis, dan/atau SNI) | C9: 1
B11: kerusakan Pondasi
A12: 1 | B12: Pondasi diindikasi dalam kondisi baik | C12: 0
A13: 2 | B13: Penurunan merata pada seluruh struktur bangunan | C13: 0.2
A14: 3 | B14: Penurunan tidak merata, namun perbedaan penurunan tidak melebihi 1/250 L | C14: 0.35
A15: 4 | B15: Penurunan > 1/250 L sehingga menimbulkan kerusakan struktur atasnya. Tanah disekeliling bangunan naik | C15: 0.5
A16: 5 | B16: Bangunan miring secara kasat mata, Lantai dasar naik/menggelembung | C16: 0.7
A17: 6 | B17: Pondasi patah, bergeser akibat longsor, struktur atas menjadi rusak | C17: 0.85
A18: 7 | B18: Material, dimensi, dan konstruksi pondasi diindikasi tidak sesuai dengan persyaratan teknis (merujuk pada Rencana Teknis apabila ada, Petunjuk Teknis, dan/atau SNI) | C18: 1
B20: kerusakan air bersih
A21: 1 | B21: Sistem penyediaan air dalam kondisi baik | C21: 0
A22: 2 | B22: Kebocoran pipa terbatas ditempat yang terlihat atau mudah dicapai, keran-keran kecil rusak, sehingga biaya perbaikan kurang dari 10% biaya instalasi baru | C22: 0.2
A23: 3 | B23: Bagian-bagian kecil pemipaan bocor, motor pompa terbakar, keran-keran kecil rusak, sehingga biaya perbaikan antara 10-25% dari biaya instalasi baru | C23: 0.35
A24: 4 | B24: Pompa, motor, pipa, dan keran rusak apabila diganti atau diperbaiki memerlukan biaya antara 25-50% dari biaya instalasi baru | C24: 0.5
A25: 5 | B25: Sebagian besar pompa, sebagian besar motor terbakar, pipa utama bocor namun ditempat terbuka, beberapa keran tidak berfungsi, sehingga biaya perbaikan 50-65% dari biaya instalasi baru | C25: 0.7
A26: 6 | B26: Pompa –pompa rusak total, motor terbakar, di banyak tempat terbuka dan tutup pipa-pipa bocor keran-keran tidak berfungsi, sehingga perbaikan instalasi perlu menyeluruh, dengan perkiraan biaya lebih dari 65% dari biaya instalasi baru | C26: 0.85
A27: 7 | B27: Material, dimensi, dan konstruksi sistem penyediaan air diindikasi tidak sesuai dengan persyaratan teknis (merujuk pada Rencana Teknis apabila ada, Petunjuk Teknis, dan/atau SNI) | C27: 1

Sheet Sheet2
D6: 1 | E6: 0
D7: 2 | E7: =E6+0.167 -> 0.167 | F7: =1/6 -> 0.16666667
D8: 3 | E8: =E7+0.167 -> 0.334
D9: 4 | E9: =E8+0.167 -> 0.501
D10: 5 | E10: =E9+0.167 -> 0.668
D11: 6 | E11: =E10+0.167 -> 0.835
D12: 7 | E12: =E11+0.167 -> 1.002

Sheet Atap
B3: No. | C3: Aspek | D3: Penjelasan | E3: Perhitungan | G3: Gambar
B4: (1) | C4: (2) | D4: (3) | E4: (4) | G4: (5)
B5: 1 | C5: Rangka Atap | D5: Rangka Atap adalah struktur rangka dibawah penutup atap (reng, usuk/kasau, gording) termasuk kuda-kudanya. | E5: Luas C = luas rangka atap yang rusak (berdasarkan hasil pengukuran lapangan)
B6: 2 | C6: Penutup Atap | D6: Penutup atap adalah genteng, seng, zincalum atau bahan lain yang didigunakan sebagai penutup atap. | E6: Luas A+B = luas penutup atap ruangan
E7: Luas A = ((8/2)+1) x (1+9) x 1,3
E8: Luas B = ((7/2)+0,36) x (1+9) x 1,3
E9: Luas C = luas penutup atap yang rusak (hasil pengukuran lapangan)
E10: Presentasi tingkat kerusakan:
E11: Luas C / (Luas A+B) x 100%
C15: NO | D15: KLASIFIKASI | E15: DESKRIPSI KERUSAKAN | F15: NILAI
D16: 1 | E16: Perubahan warna pada sebagian lapisan warna penutup atap Genteng terlepas dari dudukannya Karat mulai terlihat, gording melendut | F16: 0.2
D17: 2 | E17: Reng rusak, kaso-kaso rusak. Genteng retak dan terdapat bocoran terbatas Perubahan warna pada lapisan cat meluas Karat meluas, konstruksi bergetar akibat angin | F17: 0.4
D18: 3 | E18: Struktur atap melendut, flens profil sobek, retak pada sambungan las Gording/ rangka plafond melendut Penutup atap melendut besar dengan kemungkinan runtuh | F18: 0.6
D19: 4 | E19: Baut penyambung dan plat sambungan bengkok, profil tertekuk, korosi meluas di banyak tempat Penutup atap melendut sangat besar dengan kemungkinan keruntuhan besar | F19: 0.8
D20: 5 | E20: Komponen struktur tertekuk Sambungan putus, profil tertekukl, konstruksi runtuh Rangka atap runtuh | F20: 1

Sheet Form II
B2: FORMULIR SURVEI | G2: FORMULIR II | H2: KODE SURVEI : | I2: KAB./KOTA :
B3: BANGUNAN TERKENA DAMPAK GEMPA BUMI | H3: ....................................... | I3: ........................................
B4: PROVINSI NUSA TENGGARA BARAT | H4: TANGGAL SURVEI : | I4: KECAMATAN :
B5: TAHUN 2018 | H5: .......... AGUSTUS 2018 | I5: ........................................
B6: Nama Instansi/Pemilik Bangunan | D6: :
B7: Nama Bangunan | D7: :
B8: Alamat | D8: :
B9: Koordinat | D9: : | E9: (x) | F9: (y) | G9: (diisi dengan format desimal)
B10: Luas Bangunan | D10: : | F10: m2 | H10: Jumlah Lantai :
B11: Tipe Bangunan | D11: : | E11: Semi Permanen/Permanen (coret yang tidak sesuai)
B12: NO | C12: Komponen Bangunan | D12: Sub Komponen | F12: BOBOT
F13: Terhadap | G13: Bobot | H13: Tingkat | I13: Hasil
F14: Seluruh Bangunan | G14: Maksimum | H14: Kerusakan *) | I14: Kerusakan
F15: (%) | G15: (%) | H15: (%) | I15: (%)
B16: (1) | C16: (2) | D16: (3) | F16: (4) | G16: (5) | H16: (6) | I16: f = (4) x (6)
B17: 1 | C17: PONDASI | D17: Pondasi | F17: 10 | G17: 15 | H17: 0 | I17: =F17*H17/100 -> 0
B18: 2 | C18: STRUKTUR | D18: Kolom, Balok, dan Pelat | F18: 29 | G18: 30 | H18: 0 | I18: =F18*H18/100 -> 0
G19: N>30 | H19: rusak berat
B20: 3 | C20: ATAP | D20: Rangka Atap | F20: 8 | G20: 30 | H20: 0 | I20: =F20*H20/100 -> 0
D21: Penutup Atap | F21: 2 | G21: 100 | H21: 0 | I21: =F21*H21/100 -> 0
B22: 4 | C22: PLAFOND | D22: Rangka Langit-langit | F22: 3.5 | G22: 100 | H22: 10 | I22: =F22*H22/100 -> 0.35
D23: Penutup Langit-langit | F23: 4.5 | G23: 100 | H23: 10 | I23: =F23*H23/100 -> 0.45
B24: 5 | C24: DINDING | D24: Batu bata/Partisi | F24: 4.5 | G24: 100 | H24: 10 | I24: =F24*H24/100 -> 0.45
B25: =IF(C25="Tidak Rusak",0,IF(C25="Rusak Ringan",1,IF(C25="Rusak Sedang",2,IF(C25="Rusak Berat",3,"False")))) -> 1 | C25: =IF(I37<=30,"Rusak Ringan",IF(I37>45,"Rusak Berat","Rusak Sedang")) -> Rusak Ringan | D25: Plesteran | F25: 1.75 | G25: 100 | H25: 10 | I25: =F25*H25/100 -> 0.175
B26: =IF(C26="Tidak Rusak",0,IF(C26="Rusak Sedang",1,IF(C26="Rusak Berat",4,"False"))) -> 0 | C26: =IF(H17=0,"Tidak Rusak",IF(H17<=15,"Rusak Sedang",IF(H17>15,"Rusak Berat","False"))) -> Tidak Rusak | D26: Kaca | F26: 1.25 | G26: 100 | H26: 10 | I26: =F26*H26/100 -> 0.125
B27: =IF(C27="Tidak Rusak",0,IF(C27="Rusak Sedang",1,IF(C27="Rusak Berat",4,"False"))) -> 0 | C27: =IF(H18=0,"Tidak Rusak",IF(H18<=30,"Rusak Sedang",IF(H18>30,"Rusak Berat","False"))) -> Tidak Rusak | D27: Pintu | F27: 1 | G27: 100 | H27: 10 | I27: =F27*H27/100 -> 0.1
B28: =IF(C28="Tidak Rusak",0,IF(C28="Rusak Sedang",1,IF(C28="Rusak Berat",4,"False"))) -> 0 | C28: =IF(H20=0,"Tidak Rusak",IF(H20<=30,"Rusak Sedang",IF(H20>30,"Rusak Berat","False"))) -> Tidak Rusak | D28: Kusen | F28: 1.5 | G28: 100 | H28: 10 | I28: =F28*H28/100 -> 0.15
B29: 6 | C29: LANTAI | D29: Penutup Lantai | F29: 10 | G29: 100 | H29: 10 | I29: =F29*H29/100 -> 1
B30: 7 | C30: UTILITAS | D30: Instalasi Listrik | F30: 5 | G30: 100 | H30: 10 | I30: =F30*H30/100 -> 0.5
B31: =B26+B27+B28 -> 0 | C31: =IF(B31=0,"Tidak Rusak",IF(B31<=3,"Rusak Sedang",IF(B31>=4,"Rusak Berat","False"))) -> Tidak Rusak | D31: Instalasi Air | F31: 1.5 | G31: 100 | H31: 10 | I31: =F31*H31/100 -> 0.15
B32: =IF(C31="Tidak Rusak",0,IF(C31="Rusak Sedang",2,IF(C31="Rusak Berat",3,"False"))) -> 0 | D32: Drainase Limbah | F32: 1.5 | G32: 100 | H32: 10 | I32: =F32*H32/100 -> 0.15
B33: 8 | C33: FINISHING | D33: Finishing Struktur | F33: 1 | G33: 100 | H33: 10 | I33: =F33*H33/100 -> 0.1
D34: Finishing Langit-langit | F34: 4 | G34: 100 | H34: 10 | I34: =F34*H34/100 -> 0.4
D35: Finishing Dinding | F35: 6 | G35: 100 | H35: 10 | I35: =F35*H35/100 -> 0.6
D36: Finishing Kusen/Pintu | F36: 4 | G36: 100 | H36: 10 | I36: =F36*H36/100 -> 0.4
D37: Jumlah | F37: =SUM(F17:F36) -> 100 | I37: =SUM(I17:I36) -> 5.1
D38: Tingkat Kerusakan | I38: =IF(B32<B25,C25,C31) -> Rusak Ringan
B39: Ket : *) Diisi sesuai tingkat kerusakan dengan range 0 - 100 %
B40: SKETSA DENAH BANGUNAN
H44: TIM SURVEI :
...

Sheet Sheet4
B2: FORMULIR PENILAIAN KERUSAKAN BANGUNAN
B4: Nama Sekolah | D4: : | E4: SDN 1 Tegal
B5: NPSN | D5: : | E5: 20….
B6: Nama Bangunan | D6: : | E6: Bangunan Kelas 1 -3
B7: NUP (No Urut Perolehan) | D7: :
B8: Alamat | D8: : | E8: Jl. Timur Barat
B9: Kabupaten/Kota | D9: : | E9: Kabupaten | H9: Provinsi
B10: Koordinat | D10: :
B11: Luas Bangunan | D11: : | E11: 100 | F11: m2 | O11: Jumlah Lantai : | S11: 1
B13: NO | C13: SISTEM | D13: KOMPONEN | F13: SATUAN | G13: VOLUME SELURUH KOMPONEN | H13: TAHAP 1 - PENGAMATAN VISUAL ADA / TDKNYA KERUSAKAN DAN INDIKASI DAMPAK KERUSAKAN TERHADAP KESELAMATAN PEMANFAATAN RUANGAN / BANGUNAN | I13: TAHAP 2 - HITUNG VOLUME KERUSAKAN KOMPONEN BERDASARKAN KLASIFIKASI KERUSAKAN | P13: PERHITUNGAN TINGKAT KERUSAKAN KOMPONEN | X13: BOBOT KOMPONEN | Y13: TINGKAT KERUSAKAN KOMPONEN THD MASSA BANGUNAN
I14: Tdk Rusak | J14: Rusak, dengan Tingkat Kerusakan: | O14: Komponen Tdk Sesuai / Tdk Ada
J15: Sangat Ringan | K15: Ringan | L15: Sedang | M15: Berat | N15: Sangat Berat | P15: 1 | Q15: 2 | R15: 3 | S15: 4 | T15: 5 | U15: 6 | V15: 7 | W15: TOTAL
I16: 1 | J16: 2 | K16: 3 | L16: 4 | M16: 5 | N16: 6 | O16: 7 | P16: 0 | Q16: =P16+0.167 -> 0.167 | R16: =Q16+0.167 -> 0.334 | S16: =R16+0.167 -> 0.501 | T16: =S16+0.167 -> 0.668 | U16: =T16+0.167 -> 0.835 | V16: 1
B17: (1) | C17: (2) | D17: (3) | F17: (4) | G17: (5) | H17: (6) | I17: (7) | J17: (8) | K17: (9) | L17: (10) | M17: (11) | N17: (12) | O17: (13) | P17: (14) | Q17: (15) | R17: (16) | S17: (17) | T17: (18) | U17: (19) | V17: (20) | W17: (21) | X17: (22) | Y17: (23)
B18: 1 | C18: STRUKTUR | D18: Pondasi | F18: Estimasi | I18: Tidak ada kerusakan | W18: =IF($H$35="Rusak Berat","",VLOOKUP(I18,Sheet5!B12:C18,2,FALSE)) -> #N/A | X18: 0.12 | Y18: =IF(H35="Rusak Berat","",IF(I35="Rusak Berat","",W18*X18)) -> #N/A
D19: Kolom | F19: unit | G19: 10 | O19: 10 | P19: =IF($H$35="Rusak Berat","",IF($W$18>0.2,"",I19/G19*$P$16)) -> #N/A | Q19: =IF($H$35="Rusak Berat","",IF($W$18>0.2,"",J19/G19*$Q$16)) -> #N/A | R19: =IF($H$35="Rusak Berat","",IF($W$18>0.2,"",K19/G19*$R$16)) -> #N/A | S19: =IF($H$35="Rusak Berat","",IF($W$18>0.2,"",L19/G19*$S$16)) -> #N/A | T19: =IF($H$35="Rusak Berat","",IF($W$18>0.2,"",M19/G19*$T$16)) -> #N/A | U19: =IF($H$35="Rusak Berat","",IF($W$18>0.2,"",N19/G19*$U$16)) -> #N/A | V19: =IF($H$35="Rusak Berat","",IF($W$18>0.2,"",O19/G19*$V$16)) -> #N/A | W19: =IF($H$35="Rusak Berat","",IF($W$18>0.2,"",SUM(P19:V19))) -> #N/A | X19: 0.06 | Y19: =IF(H35="Rusak Berat","",IF(I35="Rusak Berat","",W19*X19)) -> #N/A
D20: Balok | F20: unit | G20: 4 | P20: =IF($H$35="Rusak Berat","",IF($W$18>0.2,"",I20/G20*$P$16)) -> #N/A | Q20: =IF($H$35="Rusak Berat","",IF($W$18>0.2,"",J20/G20*$Q$16)) -> #N/A | R20: =IF($H$35="Rusak Berat","",IF($W$18>0.2,"",K20/G20*$R$16)) -> #N/A | S20: =IF($H$35="Rusak Berat","",IF($W$18>0.2,"",L20/G20*$S$16)) -> #N/A | T20: =IF($H$35="Rusak Berat","",IF($W$18>0.2,"",M20/G20*$T$16)) -> #N/A | U20: =IF($H$35="Rusak Berat","",IF($W$18>0.2,"",N20/G20*$U$16)) -> #N/A | V20: =IF($H$35="Rusak Berat","",IF($W$18>0.2,"",O20/G20*$V$16)) -> #N/A | W20: =IF($H$35="Rusak Berat","",IF($W$18>0.2,"",SUM(P20:V20))) -> #N/A | X20: 0.05 | Y20: =IF(H35="Rusak Berat","",IF(I35="Rusak Berat","",W20*X20)) -> #N/A
D21: Plat Lantai | F21: m2 | G21: 10 | P21: =IF($H$35="Rusak Berat","",IF($W$18>0.2,"",I21/G21*$P$16)) -> #N/A | Q21: =IF($H$35="Rusak Berat","",IF($W$18>0.2,"",J21/G21*$Q$16)) -> #N/A | R21: =IF($H$35="Rusak Berat","",IF($W$18>0.2,"",K21/G21*$R$16)) -> #N/A | S21: =IF($H$35="Rusak Berat","",IF($W$18>0.2,"",L21/G21*$S$16)) -> #N/A | T21: =IF($H$35="Rusak Berat","",IF($W$18>0.2,"",M21/G21*$T$16)) -> #N/A | U21: =IF($H$35="Rusak Berat","",IF($W$18>0.2,"",N21/G21*$U$16)) -> #N/A | V21: =IF($H$35="Rusak Berat","",IF($W$18>0.2,"",O21/G21*$V$16)) -> #N/A | W21: =IF($H$35="Rusak Berat","",IF($W$18>0.2,"",SUM(P21:V21))) -> #N/A | X21: 0 | Y21: =IF(H35="Rusak Berat","",IF(I35="Rusak Berat","",W21*X21)) -> #N/A
D22: Atap | F22: % | G22: 100 | P22: =IF($H$35="Rusak Berat","",IF($W$18>0.2,"",IF((SUM($W$19:$W$21)/3)>0.3,"",I22/G22*100*$P$16))) -> #N/A | Q22: =IF($H$35="Rusak Berat","",IF($W$18>0.2,"",IF((SUM($W$19:$W$21)/3)>0.3,"",J22/G22*100*$Q$16))) -> #N/A | R22: =IF($H$35="Rusak Berat","",IF($W$18>0.2,"",IF((SUM($W$19:$W$21)/3)>0.3,"",K22/G22*100*$R$16))) -> #N/A | S22: =IF($H$35="Rusak Berat","",IF($W$18>0.2,"",IF((SUM($W$19:$W$21)/3)>0.3,"",L22/G22*100*$S$16))) -> #N/A | T22: =IF($H$35="Rusak Berat","",IF($W$18>0.2,"",IF((SUM($W$19:$W$21)/3)>0.3,"",M22/G22*100*$T$16))) -> #N/A | U22: =IF($H$35="Rusak Berat","",IF($W$18>0.2,"",IF((SUM($W$19:$W$21)/3)>0.3,"",N22/G22*100*$U$16))) -> #N/A | V22: =IF($H$35="Rusak Berat","",IF($W$18>0.2,"",IF((SUM($W$19:$W$21)/3)>0.3,"",O22/G22*100*$V$16))) -> #N/A | W22: =IF($H$35="Rusak Berat","",IF($W$18>0.2,"",IF((SUM($W$19:$W$21)/3)>0.3,"",SUM(P22:V22)))) -> #N/A | X22: 0.105 | Y22: =IF(H35="Rusak Berat","",IF(I35="Rusak Berat","",W22*X22)) -> #N/A
C23: ARSITEKTUR | D23: Dinding / Partisi | F23: m2 | G23: 100 | P23: =IF($H$35="Rusak Berat","",IF($W$18>0.2,"",IF((SUM($W$19:$W$21)/3)>0.3,"",IF($W$22>0.5,"",I23/G23*$P$16)))) -> #N/A | Q23: =IF($H$35="Rusak Berat","",IF($W$18>0.2,"",IF((SUM($W$19:$W$21)/3)>0.3,"",IF($W$22>0.5,"",J23/G23*$Q$16)))) -> #N/A | R23: =IF($H$35="Rusak Berat","",IF($W$18>0.2,"",IF((SUM($W$19:$W$21)/3)>0.3,"",IF($W$22>0.5,"",K23/G23*$R$16)))) -> #N/A | S23: =IF($H$35="Rusak Berat","",IF($W$18>0.2,"",IF((SUM($W$19:$W$21)/3)>0.3,"",IF($W$22>0.5,"",L23/G23*$S$16)))) -> #N/A | T23: =IF($H$35="Rusak Berat","",IF($W$18>0.2,"",IF((SUM($W$19:$W$21)/3)>0.3,"",IF($W$22>0.5,"",M23/G23*$T$16)))) -> #N/A | U23: =IF($H$35="Rusak Berat","",IF($W$18>0.2,"",IF((SUM($W$19:$W$21)/3)>0.3,"",IF($W$22>0.5,"",N23/G23*$U$16)))) -> #N/A | V23: =IF($H$35="Rusak Berat","",IF($W$18>0.2,"",IF((SUM($W$19:$W$21)/3)>0.3,"",IF($W$22>0.5,"",O23/G23*$V$16)))) -> #N/A | W23: =IF($H$35="Rusak Berat","",IF($W$18>0.2,"",IF((SUM($W$19:$W$21)/3)>0.3,"",IF($W$22>0.5,"",SUM(P23:V23))))) -> #N/A | X23: 0.26 | Y23: =IF(H35="Rusak Berat","",IF(I35="Rusak Berat","",W23*X23)) -> #N/A
B24: 2 | D24: Lantai | F24: m2 | G24: 1 | P24: =IF($H$35="Rusak Berat","",IF($I$35="Rusak Berat","",I24/G24*$P$16)) -> #N/A | Q24: =IF($H$35="Rusak Berat","",IF($I$35="Rusak Berat","",J24/G24*$Q$16)) -> #N/A | R24: =IF($H$35="Rusak Berat","",IF($I$35="Rusak Berat","",K24/G24*$R$16)) -> #N/A | S24: =IF($H$35="Rusak Berat","",IF($I$35="Rusak Berat","",L24/G24*$S$16)) -> #N/A | T24: =IF($H$35="Rusak Berat","",IF($I$35="Rusak Berat","",M24/G24*$T$16)) -> #N/A | U24: =IF($H$35="Rusak Berat","",IF($I$35="Rusak Berat","",N24/G24*$U$16)) -> #N/A | V24: =IF($H$35="Rusak Berat","",IF($I$35="Rusak Berat","",O24/G24*$V$16)) -> #N/A | W24: =IF($H$35="Rusak Berat","",IF($I$35="Rusak Berat","",SUM(P24:V24))) -> #N/A | X24: 0.15 | Y24: =IF(H35="Rusak Berat","",IF(I35="Rusak Berat","",W24*X24)) -> #N/A
D25: Kusen | F25: unit | G25: 4 | P25: =IF($H$35="Rusak Berat","",IF($I$35="Rusak Berat","",I25/G25*$P$16)) -> #N/A | Q25: =IF($H$35="Rusak Berat","",IF($I$35="Rusak Berat","",J25/G25*$Q$16)) -> #N/A | R25: =IF($H$35="Rusak Berat","",IF($I$35="Rusak Berat","",K25/G25*$R$16)) -> #N/A | S25: =IF($H$35="Rusak Berat","",IF($I$35="Rusak Berat","",L25/G25*$S$16)) -> #N/A | T25: =IF($H$35="Rusak Berat","",IF($I$35="Rusak Berat","",M25/G25*$T$16)) -> #N/A | U25: =IF($H$35="Rusak Berat","",IF($I$35="Rusak Berat","",N25/G25*$U$16)) -> #N/A | V25: =IF($H$35="Rusak Berat","",IF($I$35="Rusak Berat","",O25/G25*$V$16)) -> #N/A | W25: =IF($H$35="Rusak Berat","",IF($I$35="Rusak Berat","",SUM(P25:V25))) -> #N/A | X25: 0 | Y25: =IF(H35="Rusak Berat","",IF(I35="Rusak Berat","",W25*X25)) -> #N/A
D26: Pintu | F26: unit | G26: 4 | P26: =IF($H$35="Rusak Berat","",IF($I$35="Rusak Berat","",I26/G26*$P$16)) -> #N/A | Q26: =IF($H$35="Rusak Berat","",IF($I$35="Rusak Berat","",J26/G26*$Q$16)) -> #N/A | R26: =IF($H$35="Rusak Berat","",IF($I$35="Rusak Berat","",K26/G26*$R$16)) -> #N/A | S26: =IF($H$35="Rusak Berat","",IF($I$35="Rusak Berat","",L26/G26*$S$16)) -> #N/A | T26: =IF($H$35="Rusak Berat","",IF($I$35="Rusak Berat","",M26/G26*$T$16)) -> #N/A | U26: =IF($H$35="Rusak Berat","",IF($I$35="Rusak Berat","",N26/G26*$U$16)) -> #N/A | V26: =IF($H$35="Rusak Berat","",IF($I$35="Rusak Berat","",O26/G26*$V$16)) -> #N/A | W26: =IF($H$35="Rusak Berat","",IF($I$35="Rusak Berat","",SUM(P26:V26))) -> #N/A | X26: 0 | Y26: =IF(H35="Rusak Berat","",IF(I35="Rusak Berat","",W26*X26)) -> #N/A
D27: Jendela | F27: unit | G27: 1 | P27: =IF($H$35="Rusak Berat","",IF($I$35="Rusak Berat","",I27/G27*$P$16)) -> #N/A | Q27: =IF($H$35="Rusak Berat","",IF($I$35="Rusak Berat","",J27/G27*$Q$16)) -> #N/A | R27: =IF($H$35="Rusak Berat","",IF($I$35="Rusak Berat","",K27/G27*$R$16)) -> #N/A | S27: =IF($H$35="Rusak Berat","",IF($I$35="Rusak Berat","",L27/G27*$S$16)) -> #N/A | T27: =IF($H$35="Rusak Berat","",IF($I$35="Rusak Berat","",M27/G27*$T$16)) -> #N/A | U27: =IF($H$35="Rusak Berat","",IF($I$35="Rusak Berat","",N27/G27*$U$16)) -> #N/A | V27: =IF($H$35="Rusak Berat","",IF($I$35="Rusak Berat","",O27/G27*$V$16)) -> #N/A | W27: =IF($H$35="Rusak Berat","",IF($I$35="Rusak Berat","",SUM(P27:V27))) -> #N/A | X27: 0.065 | Y27: =IF(H35="Rusak Berat","",IF(I35="Rusak Berat","",W27*X27)) -> #N/A
D28: Plafond | F28: m2 | G28: 1 | P28: =IF($H$35="Rusak Berat","",IF($I$35="Rusak Berat","",I28/G28*$P$16)) -> #N/A | Q28: =IF($H$35="Rusak Berat","",IF($I$35="Rusak Berat","",J28/G28*$Q$16)) -> #N/A | R28: =IF($H$35="Rusak Berat","",IF($I$35="Rusak Berat","",K28/G28*$R$16)) -> #N/A | S28: =IF($H$35="Rusak Berat","",IF($I$35="Rusak Berat","",L28/G28*$S$16)) -> #N/A | T28: =IF($H$35="Rusak Berat","",IF($I$35="Rusak Berat","",M28/G28*$T$16)) -> #N/A | U28: =IF($H$35="Rusak Berat","",IF($I$35="Rusak Berat","",N28/G28*$U$16)) -> #N/A | V28: =IF($H$35="Rusak Berat","",IF($I$35="Rusak Berat","",O28/G28*$V$16)) -> #N/A | W28: =IF($H$35="Rusak Berat","",IF($I$35="Rusak Berat","",SUM(P28:V28))) -> #N/A | X28: 0.1 | Y28: =IF(H35="Rusak Berat","",IF(I35="Rusak Berat","",W28*X28)) -> #N/A
D29: Finishing Plafond | F29: % | G29: 100 | P29: =IF($H$35="Rusak Berat","",IF($I$35="Rusak Berat","",I29/G29*$P$16)) -> #N/A | Q29: =IF($H$35="Rusak Berat","",IF($I$35="Rusak Berat","",J29/G29*$Q$16)) -> #N/A | R29: =IF($H$35="Rusak Berat","",IF($I$35="Rusak Berat","",K29/G29*$R$16)) -> #N/A | S29: =IF($H$35="Rusak Berat","",IF($I$35="Rusak Berat","",L29/G29*$S$16)) -> #N/A | T29: =IF($H$35="Rusak Berat","",IF($I$35="Rusak Berat","",M29/G29*$T$16)) -> #N/A | U29: =IF($H$35="Rusak Berat","",IF($I$35="Rusak Berat","",N29/G29*$U$16)) -> #N/A | V29: =IF($H$35="Rusak Berat","",IF($I$35="Rusak Berat","",O29/G29*$V$16)) -> #N/A | W29: =IF($H$35="Rusak Berat","",IF($I$35="Rusak Berat","",SUM(P29:V29))) -> #N/A | X29: 0.03 | Y29: =IF(H35="Rusak Berat","",IF(I35="Rusak Berat","",W29*X29)) -> #N/A
D30: Finishing Dinding | F30: % | G30: 100 | P30: =IF($H$35="Rusak Berat","",IF($I$35="Rusak Berat","",I30/G30*$P$16)) -> #N/A | Q30: =IF($H$35="Rusak Berat","",IF($I$35="Rusak Berat","",J30/G30*$Q$16)) -> #N/A | R30: =IF($H$35="Rusak Berat","",IF($I$35="Rusak Berat","",K30/G30*$R$16)) -> #N/A | S30: =IF($H$35="Rusak Berat","",IF($I$35="Rusak Berat","",L30/G30*$S$16)) -> #N/A | T30: =IF($H$35="Rusak Berat","",IF($I$35="Rusak Berat","",M30/G30*$T$16)) -> #N/A | U30: =IF($H$35="Rusak Berat","",IF($I$35="Rusak Berat","",N30/G30*$U$16)) -> #N/A | V30: =IF($H$35="Rusak Berat","",IF($I$35="Rusak Berat","",O30/G30*$V$16)) -> #N/A | W30: =IF($H$35="Rusak Berat","",IF($I$35="Rusak Berat","",SUM(P30:V30))) -> #N/A | X30: 0.04 | Y30: =IF(H35="Rusak Berat","",IF(I35="Rusak Berat","",W30*X30)) -> #N/A
D31: Finishing Kusen & Pintu | F31: % | G31: 100 | P31: =IF($H$35="Rusak Berat","",IF($I$35="Rusak Berat","",I31/G31*$P$16)) -> #N/A | Q31: =IF($H$35="Rusak Berat","",IF($I$35="Rusak Berat","",J31/G31*$Q$16)) -> #N/A | R31: =IF($H$35="Rusak Berat","",IF($I$35="Rusak Berat","",K31/G31*$R$16)) -> #N/A | S31: =IF($H$35="Rusak Berat","",IF($I$35="Rusak Berat","",L31/G31*$S$16)) -> #N/A | T31: =IF($H$35="Rusak Berat","",IF($I$35="Rusak Berat","",M31/G31*$T$16)) -> #N/A | U31: =IF($H$35="Rusak Berat","",IF($I$35="Rusak Berat","",N31/G31*$U$16)) -> #N/A | V31: =IF($H$35="Rusak Berat","",IF($I$35="Rusak Berat","",O31/G31*$V$16)) -> #N/A | W31: =IF($H$35="Rusak Berat","",IF($I$35="Rusak Berat","",SUM(P31:V31))) -> #N/A | X31: 0 | Y31: =IF(H35="Rusak Berat","",IF(I35="Rusak Berat","",W31*X31)) -> #N/A
B32: 3 | C32: UTILITAS | D32: Instalasi Listrik | F32: Estimasi | I32: Tidak ada kerusakan | W32: =IF(H35="Rusak Berat","",IF(I35="Rusak Berat","",VLOOKUP(I32,Sheet5!B3:C9,2,FALSE))) -> #N/A | X32: 0.01 | Y32: =IF(H35="Rusak Berat","",IF(I35="Rusak Berat","",W32*X32)) -> #N/A
D33: Instalasi Air Bersih | F33: Estimasi | I33: tidak ada kerusakan | W33: =IF(H35="Rusak Berat","",IF(I35="Rusak Berat","",VLOOKUP(I33,Sheet5!B21:C27,2,FALSE))) -> #N/A | X33: 0.01 | Y33: =IF(H35="Rusak Berat","",IF(I35="Rusak Berat","",W33*X33)) -> #N/A
D34: Drainase Limbah | F34: Unit | G34: 1 | P34: =IF($H$35="Rusak Berat","",IF($I$35="Rusak Berat","",I34/G34*$P$16)) -> #N/A | Q34: =IF($H$35="Rusak Berat","",IF($I$35="Rusak Berat","",J34/G34*$Q$16)) -> #N/A | R34: =IF($H$35="Rusak Berat","",IF($I$35="Rusak Berat","",K34/G34*$R$16)) -> #N/A | S34: =IF($H$35="Rusak Berat","",IF($I$35="Rusak Berat","",L34/G34*$S$16)) -> #N/A | T34: =IF($H$35="Rusak Berat","",IF($I$35="Rusak Berat","",M34/G34*$T$16)) -> #N/A | U34: =IF($H$35="Rusak Berat","",IF($I$35="Rusak Berat","",N34/G34*$U$16)) -> #N/A | V34: =IF($H$35="Rusak Berat","",IF($I$35="Rusak Berat","",O34/G34*$V$16)) -> #N/A | W34: =IF($H$35="Rusak Berat","",IF($I$35="Rusak Berat","",SUM(P34:V34))) -> #N/A | X34: 0 | Y34: =IF(H35="Rusak Berat","",IF(I35="Rusak Berat","",W34*X34)) -> #N/A
H35: =IF(H18=Sheet1!G5,"Rusak Berat",IF(H19=Sheet1!G5,"Rusak Berat",IF(H20=Sheet1!G5,"Rusak Berat",IF(H21=Sheet1!G5,"Rusak Berat",IF(H22=Sheet1!G5,"Rusak Berat",IF(H23=Sheet1!G5,"Rusak Berat",IF(H18=Sheet1!G6,"Hitung Kerusakan",IF(H19=Sheet1!G6,"Hitung Kerusakan",IF(H20=Sheet1!G6,"Hitung Kerusakan",IF(H21=Sheet1!G6,"Hitung Kerusakan",IF(H22=Sheet1!G6,"Hitung Kerusakan","Cek Kerusakan Komponen Lain"))))))))))) -> Cek Kerusakan Komponen Lain | I35: =IF(W18>0.2,"Rusak Berat",IF((SUM(W19:W21)/3)>0.3,"Rusak Berat",IF(W22>0.5,"Rusak Berat",IF(W23>0.8,"Rusak Berat","Hitung Kerusakan Komponen")))) -> #N/A | P35: TOTAL NILAI KERUSAKAN MASSA BANGUNAN= | Y35: =IF(H35="Rusak Berat","",IF(I35="Rusak Berat","",SUM(Y18:Y34))) -> #N/A
P37: KESIMPULAN TINGKAT KERUSAKAN MASSA BANGUNAN= | Y37: =IF(H35="Rusak Berat","Rusak Berat",IF(I35="Rusak Berat","Rusak Berat",Y38)) -> #N/A
Y38: =IF(Y35=0,"Tidak Ada Kerusakan",IF(Y35<=0.3,"Rusak Ringan",IF(Y35>0.45,"Rusak Berat","Rusak Sedang"))) -> #N/A
W40: Tingkat Kerusakan
W41: Ringan | Y41: : ≤ 30%
B42: SKETSA DENAH BANGUNAN | W42: Sedang | Y42: : > 30% - 45%
W43: Berat | Y43: : > 45%
W45: TIM SURVEI :
W46: Petugas Survey
...
